Using  cuda
Process Process-1:
Traceback (most recent call last):
  File "/usr/common/software/pytorch/v1.2.0-gpu/lib/python3.6/multiprocessing/process.py", line 258, in _bootstrap
    self.run()
  File "/usr/common/software/pytorch/v1.2.0-gpu/lib/python3.6/multiprocessing/process.py", line 93, in run
    self._target(*self._args, **self._kwargs)
  File "/global/homes/d/danieltm/.local/cori/pytorchv1.2.0-gpu/lib/python3.6/site-packages/wandb/wandb_agent.py", line 64, in _start
    function()
  File "src/sweep.py", line 90, in train
    loss = criterion(outputs, labels)
  File "/usr/common/software/pytorch/v1.2.0-gpu/lib/python3.6/site-packages/torch/nn/modules/module.py", line 547, in __call__
    result = self.forward(*input, **kwargs)
  File "/usr/common/software/pytorch/v1.2.0-gpu/lib/python3.6/site-packages/torch/nn/modules/loss.py", line 916, in forward
    ignore_index=self.ignore_index, reduction=self.reduction)
  File "/usr/common/software/pytorch/v1.2.0-gpu/lib/python3.6/site-packages/torch/nn/functional.py", line 1995, in cross_entropy
    return nll_loss(log_softmax(input, 1), target, weight, None, ignore_index, None, reduction)
  File "/usr/common/software/pytorch/v1.2.0-gpu/lib/python3.6/site-packages/torch/nn/functional.py", line 1822, in nll_loss
    .format(input.size(0), target.size(0)))
ValueError: Expected input batch_size (1428) to match target batch_size (4).
