Using  cuda
Traceback (most recent call last):
  File "src/sweep_test.py", line 138, in <module>
    main()
  File "src/sweep_test.py", line 104, in main
    loss = criterion(outputs, labels)
  File "/usr/common/software/pytorch/v1.2.0-gpu/lib/python3.6/site-packages/torch/nn/modules/module.py", line 547, in __call__
    result = self.forward(*input, **kwargs)
  File "/usr/common/software/pytorch/v1.2.0-gpu/lib/python3.6/site-packages/torch/nn/modules/loss.py", line 916, in forward
    ignore_index=self.ignore_index, reduction=self.reduction)
  File "/usr/common/software/pytorch/v1.2.0-gpu/lib/python3.6/site-packages/torch/nn/functional.py", line 1995, in cross_entropy
    return nll_loss(log_softmax(input, 1), target, weight, None, ignore_index, None, reduction)
  File "/usr/common/software/pytorch/v1.2.0-gpu/lib/python3.6/site-packages/torch/nn/functional.py", line 1822, in nll_loss
    .format(input.size(0), target.size(0)))
ValueError: Expected input batch_size (7188) to match target batch_size (4).
