Using  cuda
Process Process-1:
Traceback (most recent call last):
  File "/usr/common/software/pytorch/v1.2.0-gpu/lib/python3.6/multiprocessing/process.py", line 258, in _bootstrap
    self.run()
  File "/usr/common/software/pytorch/v1.2.0-gpu/lib/python3.6/multiprocessing/process.py", line 93, in run
    self._target(*self._args, **self._kwargs)
  File "/global/homes/d/danieltm/.local/cori/pytorchv1.2.0-gpu/lib/python3.6/site-packages/wandb/wandb_agent.py", line 64, in _start
    function()
  File "src/sweep.py", line 89, in train
    outputs = model(inputs)
  File "/usr/common/software/pytorch/v1.2.0-gpu/lib/python3.6/site-packages/torch/nn/modules/module.py", line 547, in __call__
    result = self.forward(*input, **kwargs)
  File "/global/u2/d/danieltm/Pipeline_Toy/src/models/convNet.py", line 22, in forward
    x = F.relu(self.fc1(x))
  File "/usr/common/software/pytorch/v1.2.0-gpu/lib/python3.6/site-packages/torch/nn/modules/module.py", line 547, in __call__
    result = self.forward(*input, **kwargs)
  File "/usr/common/software/pytorch/v1.2.0-gpu/lib/python3.6/site-packages/torch/nn/modules/linear.py", line 87, in forward
    return F.linear(input, self.weight, self.bias)
  File "/usr/common/software/pytorch/v1.2.0-gpu/lib/python3.6/site-packages/torch/nn/functional.py", line 1369, in linear
    ret = torch.addmm(bias, input, weight.t())
RuntimeError: size mismatch, m1: [4 x 17075], m2: [14343 x 1524] at /global/cscratch1/sd/swowner/pytorch-build/pytorch/v1.2.0-gpu/pytorch/aten/src/THC/generic/THCTensorMathBlas.cu:273
